Workbook

Sheet GASTOS
C8: RESUMEN ANUAL
A10: FECHA | B10: REFERENCIA | C10: DESCRIPCIÓN | D10: MONTO BS | E10: D/C | F10: COD/CONT | G10: CONTABLE | H10: Deposito | I10: Codigo Dep | J10: Campaña | K10: PROVEEDOR | L10: Columna2 | M10: COD/SER | N10: SERVICIO | O10: Columna1 | P10: TASA | Q10: MONTO EN $ | R10: BANCO | S10: OBSERVACIONES | T10: NªGASTO | U10: Nº | V10: CLASIFICACION | W10: SEDE
A11: 46030 | B11: 13264946969 | C11: COM. TRF. CR.INM.OB | D11: -768.54 | E11: D | F11: =VLOOKUP(Tabla3[[#This Row],[CONTABLE]],'SAPROV (2)'!L:M,2,FALSE) -> #N/A | H11: ADMINISTRATIVOS | I11: =VLOOKUP(Tabla3[[#This Row],[Deposito]],'SAPROV (2)'!D:E,2,FALSE) -> A01 | K11: COMISIONES BANCARIAS | L11: =VLOOKUP(Tabla3[[#This Row],[PROVEEDOR]],'SAPROV (2)'!A:B,2,FALSE) -> 04 | M11: =VLOOKUP(Tabla3[[#This Row],[SERVICIO]],'SAPROV (2)'!I:J,2,FALSE) -> SERV0060 | N11: ?COMISIONES BANCARIAS | P11: =VLOOKUP(Tabla3[[#This Row],[FECHA]],TASA[],2,FALSE) -> 321.03 | Q11: =D11/P11 -> -2.3939819 | R11: BANESCO
A12: 46030 | B12: 13264948035 | C12: COM. TRF. CR.INM.OB | D12: -422.7 | E12: D | F12: =VLOOKUP(Tabla3[[#This Row],[CONTABLE]],'SAPROV (2)'!L:M,2,FALSE) -> #N/A | H12: ADMINISTRATIVOS | I12: =VLOOKUP(Tabla3[[#This Row],[Deposito]],'SAPROV (2)'!D:E,2,FALSE) -> A01 | K12: COMISIONES BANCARIAS | L12: =VLOOKUP(Tabla3[[#This Row],[PROVEEDOR]],'SAPROV (2)'!A:B,2,FALSE) -> 04 | M12: =VLOOKUP(Tabla3[[#This Row],[SERVICIO]],'SAPROV (2)'!I:J,2,FALSE) -> SERV0060 | N12: ?COMISIONES BANCARIAS | P12: =VLOOKUP(Tabla3[[#This Row],[FECHA]],TASA[],2,FALSE) -> 321.03 | Q12: =D12/P12 -> -1.3166994 | R12: BANESCO
A13: 46030 | B13: 13264948745 | C13: COM. TRF. CR.INM.OB | D13: -238.08 | E13: D | F13: =VLOOKUP(Tabla3[[#This Row],[CONTABLE]],'SAPROV (2)'!L:M,2,FALSE) -> #N/A | H13: ADMINISTRATIVOS | I13: =VLOOKUP(Tabla3[[#This Row],[Deposito]],'SAPROV (2)'!D:E,2,FALSE) -> A01 | K13: COMISIONES BANCARIAS | L13: =VLOOKUP(Tabla3[[#This Row],[PROVEEDOR]],'SAPROV (2)'!A:B,2,FALSE) -> 04 | M13: =VLOOKUP(Tabla3[[#This Row],[SERVICIO]],'SAPROV (2)'!I:J,2,FALSE) -> SERV0060 | N13: ?COMISIONES BANCARIAS | P13: =VLOOKUP(Tabla3[[#This Row],[FECHA]],TASA[],2,FALSE) -> 321.03 | Q13: =D13/P13 -> -0.74161293 | R13: BANESCO
A14: 46030 | B14: 13264956402 | C14: COM. TRF. CR.INM.OB | D14: -548.36 | E14: D | F14: =VLOOKUP(Tabla3[[#This Row],[CONTABLE]],'SAPROV (2)'!L:M,2,FALSE) -> #N/A | H14: ADMINISTRATIVOS | I14: =VLOOKUP(Tabla3[[#This Row],[Deposito]],'SAPROV (2)'!D:E,2,FALSE) -> A01 | K14: COMISIONES BANCARIAS | L14: =VLOOKUP(Tabla3[[#This Row],[PROVEEDOR]],'SAPROV (2)'!A:B,2,FALSE) -> 04 | M14: =VLOOKUP(Tabla3[[#This Row],[SERVICIO]],'SAPROV (2)'!I:J,2,FALSE) -> SERV0060 | N14: ?COMISIONES BANCARIAS | P14: =VLOOKUP(Tabla3[[#This Row],[FECHA]],TASA[],2,FALSE) -> 321.03 | Q14: =D14/P14 -> -1.708127 | R14: BANESCO
A15: 46031 | B15: 13265531340 | C15: COM. TRF. CR.INM.OB | D15: -3000 | E15: D | F15: =VLOOKUP(Tabla3[[#This Row],[CONTABLE]],'SAPROV (2)'!L:M,2,FALSE) -> #N/A | H15: ADMINISTRATIVOS | I15: =VLOOKUP(Tabla3[[#This Row],[Deposito]],'SAPROV (2)'!D:E,2,FALSE) -> A01 | K15: COMISIONES BANCARIAS | L15: =VLOOKUP(Tabla3[[#This Row],[PROVEEDOR]],'SAPROV (2)'!A:B,2,FALSE) -> 04 | M15: =VLOOKUP(Tabla3[[#This Row],[SERVICIO]],'SAPROV (2)'!I:J,2,FALSE) -> SERV0060 | N15: ?COMISIONES BANCARIAS | P15: =VLOOKUP(Tabla3[[#This Row],[FECHA]],TASA[],2,FALSE) -> 325.39 | Q15: =D15/P15 -> -9.2197056 | R15: BANESCO
A16: 46031 | B16: 13265532349 | C16: COM. TRF. CR.INM.OB | D16: -900 | E16: D | F16: =VLOOKUP(Tabla3[[#This Row],[CONTABLE]],'SAPROV (2)'!L:M,2,FALSE) -> #N/A | H16: ADMINISTRATIVOS | I16: =VLOOKUP(Tabla3[[#This Row],[Deposito]],'SAPROV (2)'!D:E,2,FALSE) -> A01 | K16: COMISIONES BANCARIAS | L16: =VLOOKUP(Tabla3[[#This Row],[PROVEEDOR]],'SAPROV (2)'!A:B,2,FALSE) -> 04 | M16: =VLOOKUP(Tabla3[[#This Row],[SERVICIO]],'SAPROV (2)'!I:J,2,FALSE) -> SERV0060 | N16: ?COMISIONES BANCARIAS | P16: =VLOOKUP(Tabla3[[#This Row],[FECHA]],TASA[],2,FALSE) -> 325.39 | Q16: =D16/P16 -> -2.7659117 | R16: BANESCO
A17: 46031 | B17: 13265533768 | C17: COM. TRF. CR.INM.OB | D17: -1500 | E17: D | F17: =VLOOKUP(Tabla3[[#This Row],[CONTABLE]],'SAPROV (2)'!L:M,2,FALSE) -> #N/A | H17: ADMINISTRATIVOS | I17: =VLOOKUP(Tabla3[[#This Row],[Deposito]],'SAPROV (2)'!D:E,2,FALSE) -> A01 | K17: COMISIONES BANCARIAS | L17: =VLOOKUP(Tabla3[[#This Row],[PROVEEDOR]],'SAPROV (2)'!A:B,2,FALSE) -> 04 | M17: =VLOOKUP(Tabla3[[#This Row],[SERVICIO]],'SAPROV (2)'!I:J,2,FALSE) -> SERV0060 | N17: ?COMISIONES BANCARIAS | P17: =VLOOKUP(Tabla3[[#This Row],[FECHA]],TASA[],2,FALSE) -> 325.39 | Q17: =D17/P17 -> -4.6098528 | R17: BANESCO
A18: 46035 | B18: 13266810676 | C18: COM. TRF. CR.INM.OB | D18: -2 | E18: D | F18: =VLOOKUP(Tabla3[[#This Row],[CONTABLE]],'SAPROV (2)'!L:M,2,FALSE) -> #N/A | H18: ADMINISTRATIVOS | I18: =VLOOKUP(Tabla3[[#This Row],[Deposito]],'SAPROV (2)'!D:E,2,FALSE) -> A01 | K18: COMISIONES BANCARIAS | L18: =VLOOKUP(Tabla3[[#This Row],[PROVEEDOR]],'SAPROV (2)'!A:B,2,FALSE) -> 04 | M18: =VLOOKUP(Tabla3[[#This Row],[SERVICIO]],'SAPROV (2)'!I:J,2,FALSE) -> SERV0060 | N18: ?COMISIONES BANCARIAS | P18: =VLOOKUP(Tabla3[[#This Row],[FECHA]],TASA[],2,FALSE) -> 330.38 | Q18: =D18/P18 -> -0.0060536352 | R18: BANESCO
A19: 46035 | B19: 13266838623 | C19: COM. TRF. CR.INM.OB | D19: -48.16 | E19: D | F19: =VLOOKUP(Tabla3[[#This Row],[CONTABLE]],'SAPROV (2)'!L:M,2,FALSE) -> #N/A | H19: ADMINISTRATIVOS | I19: =VLOOKUP(Tabla3[[#This Row],[Deposito]],'SAPROV (2)'!D:E,2,FALSE) -> A01 | K19: COMISIONES BANCARIAS | L19: =VLOOKUP(Tabla3[[#This Row],[PROVEEDOR]],'SAPROV (2)'!A:B,2,FALSE) -> 04 | M19: =VLOOKUP(Tabla3[[#This Row],[SERVICIO]],'SAPROV (2)'!I:J,2,FALSE) -> SERV0060 | N19: ?COMISIONES BANCARIAS | P19: =VLOOKUP(Tabla3[[#This Row],[FECHA]],TASA[],2,FALSE) -> 330.38 | Q19: =D19/P19 -> -0.14577154 | R19: BANESCO
A20: 46035 | B20: 13267182287 | C20: COM. TRF. CR.INM.OB | D20: -2759.29 | E20: D | F20: =VLOOKUP(Tabla3[[#This Row],[CONTABLE]],'SAPROV (2)'!L:M,2,FALSE) -> #N/A | H20: ADMINISTRATIVOS | I20: =VLOOKUP(Tabla3[[#This Row],[Deposito]],'SAPROV (2)'!D:E,2,FALSE) -> A01 | K20: COMISIONES BANCARIAS | L20: =VLOOKUP(Tabla3[[#This Row],[PROVEEDOR]],'SAPROV (2)'!A:B,2,FALSE) -> 04 | M20: =VLOOKUP(Tabla3[[#This Row],[SERVICIO]],'SAPROV (2)'!I:J,2,FALSE) -> SERV0060 | N20: ?COMISIONES BANCARIAS | P20: =VLOOKUP(Tabla3[[#This Row],[FECHA]],TASA[],2,FALSE) -> 330.38 | Q20: =D20/P20 -> -8.3518675 | R20: BANESCO
A21: 46035 | B21: 13267244404 | C21: COM. TRF. CR.INM.OB | D21: -3000 | E21: D | F21: =VLOOKUP(Tabla3[[#This Row],[CONTABLE]],'SAPROV (2)'!L:M,2,FALSE) -> #N/A | H21: ADMINISTRATIVOS | I21: =VLOOKUP(Tabla3[[#This Row],[Deposito]],'SAPROV (2)'!D:E,2,FALSE) -> A01 | K21: COMISIONES BANCARIAS | L21: =VLOOKUP(Tabla3[[#This Row],[PROVEEDOR]],'SAPROV (2)'!A:B,2,FALSE) -> 04 | M21: =VLOOKUP(Tabla3[[#This Row],[SERVICIO]],'SAPROV (2)'!I:J,2,FALSE) -> SERV0060 | N21: ?COMISIONES BANCARIAS | P21: =VLOOKUP(Tabla3[[#This Row],[FECHA]],TASA[],2,FALSE) -> 330.38 | Q21: =D21/P21 -> -9.0804528 | R21: BANESCO
A22: 46035 | B22: 13267396284 | C22: COM. TRF. CR.INM.OB | D22: -371.67 | E22: D | F22: =VLOOKUP(Tabla3[[#This Row],[CONTABLE]],'SAPROV (2)'!L:M,2,FALSE) -> #N/A | H22: ADMINISTRATIVOS | I22: =VLOOKUP(Tabla3[[#This Row],[Deposito]],'SAPROV (2)'!D:E,2,FALSE) -> A01 | K22: COMISIONES BANCARIAS | L22: =VLOOKUP(Tabla3[[#This Row],[PROVEEDOR]],'SAPROV (2)'!A:B,2,FALSE) -> 04 | M22: =VLOOKUP(Tabla3[[#This Row],[SERVICIO]],'SAPROV (2)'!I:J,2,FALSE) -> SERV0060 | N22: ?COMISIONES BANCARIAS | P22: =VLOOKUP(Tabla3[[#This Row],[FECHA]],TASA[],2,FALSE) -> 330.38 | Q22: =D22/P22 -> -1.1249773 | R22: BANESCO
... A138: 46042 | B138: 105405571 | C138: MANT AFIL CANAL VIRT DIC25 | D138: -450.92 | E138: D | F138: =VLOOKUP(Tabla3[[#This Row],[CONTABLE]],'SAPROV (2)'!L:M,2,FALSE) -> #N/A | H138: ADMINISTRATIVOS | I138: =VLOOKUP(Tabla3[[#This Row],[Deposito]],'SAPROV (2)'!D:E,2,FALSE) -> A01 | K138: COMISIONES BANCARIAS | L138: =VLOOKUP(Tabla3[[#This Row],[PROVEEDOR]],'SAPROV (2)'!A:B,2,FALSE) -> 04 | M138: =VLOOKUP(Tabla3[[#This Row],[SERVICIO]],'SAPROV (2)'!I:J,2,FALSE) -> SERV0060 | N138: ?COMISIONES BANCARIAS | P138: =VLOOKUP(Tabla3[[#This Row],[FECHA]],TASA[],2,FALSE) -> 344.51 | Q138: =D138/P138 -> -1.3088735 | R138: BDT
A139: 46052 | C139: CARGO EMISION EDO DE CUENTA | D139: -30 | E139: D | F139: =VLOOKUP(Tabla3[[#This Row],[CONTABLE]],'SAPROV (2)'!L:M,2,FALSE) -> #N/A | H139: ADMINISTRATIVOS | I139: =VLOOKUP(Tabla3[[#This Row],[Deposito]],'SAPROV (2)'!D:E,2,FALSE) -> A01 | K139: COMISIONES BANCARIAS | L139: =VLOOKUP(Tabla3[[#This Row],[PROVEEDOR]],'SAPROV (2)'!A:B,2,FALSE) -> 04 | M139: =VLOOKUP(Tabla3[[#This Row],[SERVICIO]],'SAPROV (2)'!I:J,2,FALSE) -> SERV0060 | N139: ?COMISIONES BANCARIAS | P139: =VLOOKUP(Tabla3[[#This Row],[FECHA]],TASA[],2,FALSE) -> 367.31 | Q139: =D139/P139 -> -0.08167488 | R139: BDT
A140: 46052 | C140: CARGO POR SERVICIO | D140: -20 | E140: D | F140: =VLOOKUP(Tabla3[[#This Row],[CONTABLE]],'SAPROV (2)'!L:M,2,FALSE) -> #N/A | H140: ADMINISTRATIVOS | I140: =VLOOKUP(Tabla3[[#This Row],[Deposito]],'SAPROV (2)'!D:E,2,FALSE) -> A01 | K140: COMISIONES BANCARIAS | L140: =VLOOKUP(Tabla3[[#This Row],[PROVEEDOR]],'SAPROV (2)'!A:B,2,FALSE) -> 04 | M140: =VLOOKUP(Tabla3[[#This Row],[SERVICIO]],'SAPROV (2)'!I:J,2,FALSE) -> SERV0060 | N140: ?COMISIONES BANCARIAS | P140: =VLOOKUP(Tabla3[[#This Row],[FECHA]],TASA[],2,FALSE) -> 367.31 | Q140: =D140/P140 -> -0.05444992 | R140: BDT
A141: 46027 | B141: 43700024375 | C141: OP.CRED.DIRT.CLTE-CLTE PJ JURIDICA ELECTRON | D141: -10.1 | E141: D | F141: =VLOOKUP(Tabla3[[#This Row],[CONTABLE]],'SAPROV (2)'!L:M,2,FALSE) -> #N/A | H141: ADMINISTRATIVOS | I141: =VLOOKUP(Tabla3[[#This Row],[Deposito]],'SAPROV (2)'!D:E,2,FALSE) -> A01 | K141: COMISIONES BANCARIAS | L141: =VLOOKUP(Tabla3[[#This Row],[PROVEEDOR]],'SAPROV (2)'!A:B,2,FALSE) -> 04 | M141: =VLOOKUP(Tabla3[[#This Row],[SERVICIO]],'SAPROV (2)'!I:J,2,FALSE) -> SERV0060 | N141: ?COMISIONES BANCARIAS | P141: =VLOOKUP(Tabla3[[#This Row],[FECHA]],TASA[],2,FALSE) -> 304.68 | Q141: =D141/P141 -> -0.033149534 | R141: MERCANTIL
A142: 46042 | B142: 43700031193 | C142: OP.CRED.DIRT. CLTE-CLTE PJ ELECTRON | D142: -10.1 | E142: D | F142: =VLOOKUP(Tabla3[[#This Row],[CONTABLE]],'SAPROV (2)'!L:M,2,FALSE) -> #N/A | H142: ADMINISTRATIVOS | I142: =VLOOKUP(Tabla3[[#This Row],[Deposito]],'SAPROV (2)'!D:E,2,FALSE) -> A01 | K142: COMISIONES BANCARIAS | L142: =VLOOKUP(Tabla3[[#This Row],[PROVEEDOR]],'SAPROV (2)'!A:B,2,FALSE) -> 04 | M142: =VLOOKUP(Tabla3[[#This Row],[SERVICIO]],'SAPROV (2)'!I:J,2,FALSE) -> SERV0060 | N142: ?COMISIONES BANCARIAS | P142: =VLOOKUP(Tabla3[[#This Row],[FECHA]],TASA[],2,FALSE) -> 344.51 | Q142: =D142/P142 -> -0.029317001 | R142: MERCANTIL
A143: 46049 | B143: 10781498729 | C143: COMISION POR TRANSFERENCIA DE FONDOS | D143: -3000 | E143: D | F143: =VLOOKUP(Tabla3[[#This Row],[CONTABLE]],'SAPROV (2)'!L:M,2,FALSE) -> #N/A | H143: ADMINISTRATIVOS | I143: =VLOOKUP(Tabla3[[#This Row],[Deposito]],'SAPROV (2)'!D:E,2,FALSE) -> A01 | K143: COMISIONES BANCARIAS | L143: =VLOOKUP(Tabla3[[#This Row],[PROVEEDOR]],'SAPROV (2)'!A:B,2,FALSE) -> 04 | M143: =VLOOKUP(Tabla3[[#This Row],[SERVICIO]],'SAPROV (2)'!I:J,2,FALSE) -> SERV0060 | N143: ?COMISIONES BANCARIAS | P143: =VLOOKUP(Tabla3[[#This Row],[FECHA]],TASA[],2,FALSE) -> 358.92 | Q143: =D143/P143 -> -8.3584086 | R143: MERCANTIL
A144: 46049 | B144: 10781498469 | C144: COMISION POR TRANSFERENCIA DE FONDOS | D144: -3000 | E144: D | F144: =VLOOKUP(Tabla3[[#This Row],[CONTABLE]],'SAPROV (2)'!L:M,2,FALSE) -> #N/A | H144: ADMINISTRATIVOS | I144: =VLOOKUP(Tabla3[[#This Row],[Deposito]],'SAPROV (2)'!D:E,2,FALSE) -> A01 | K144: COMISIONES BANCARIAS | L144: =VLOOKUP(Tabla3[[#This Row],[PROVEEDOR]],'SAPROV (2)'!A:B,2,FALSE) -> 04 | M144: =VLOOKUP(Tabla3[[#This Row],[SERVICIO]],'SAPROV (2)'!I:J,2,FALSE) -> SERV0060 | N144: ?COMISIONES BANCARIAS | P144: =VLOOKUP(Tabla3[[#This Row],[FECHA]],TASA[],2,FALSE) -> 358.92 | Q144: =D144/P144 -> -8.3584086 | R144: MERCANTIL
A145: 46049 | B145: 10781498160 | C145: COMISION POR TRANSFERENCIA DE FONDOS | D145: -3000 | E145: D | F145: =VLOOKUP(Tabla3[[#This Row],[CONTABLE]],'SAPROV (2)'!L:M,2,FALSE) -> #N/A | H145: ADMINISTRATIVOS | I145: =VLOOKUP(Tabla3[[#This Row],[Deposito]],'SAPROV (2)'!D:E,2,FALSE) -> A01 | K145: COMISIONES BANCARIAS | L145: =VLOOKUP(Tabla3[[#This Row],[PROVEEDOR]],'SAPROV (2)'!A:B,2,FALSE) -> 04 | M145: =VLOOKUP(Tabla3[[#This Row],[SERVICIO]],'SAPROV (2)'!I:J,2,FALSE) -> SERV0060 | N145: ?COMISIONES BANCARIAS | P145: =VLOOKUP(Tabla3[[#This Row],[FECHA]],TASA[],2,FALSE) -> 358.92 | Q145: =D145/P145 -> -8.3584086 | R145: MERCANTIL
A146: 46049 | B146: 10781497975 | C146: COMISION POR TRANSFERENCIA DE FONDOS | D146: -3000 | E146: D | F146: =VLOOKUP(Tabla3[[#This Row],[CONTABLE]],'SAPROV (2)'!L:M,2,FALSE) -> #N/A | H146: ADMINISTRATIVOS | I146: =VLOOKUP(Tabla3[[#This Row],[Deposito]],'SAPROV (2)'!D:E,2,FALSE) -> A01 | K146: COMISIONES BANCARIAS | L146: =VLOOKUP(Tabla3[[#This Row],[PROVEEDOR]],'SAPROV (2)'!A:B,2,FALSE) -> 04 | M146: =VLOOKUP(Tabla3[[#This Row],[SERVICIO]],'SAPROV (2)'!I:J,2,FALSE) -> SERV0060 | N146: ?COMISIONES BANCARIAS | P146: =VLOOKUP(Tabla3[[#This Row],[FECHA]],TASA[],2,FALSE) -> 358.92 | Q146: =D146/P146 -> -8.3584086 | R146: MERCANTIL
A147: 46049 | B147: 10781497710 | C147: COMISION POR TRANSFERENCIA DE FONDOS | D147: -3000 | E147: D | F147: =VLOOKUP(Tabla3[[#This Row],[CONTABLE]],'SAPROV (2)'!L:M,2,FALSE) -> #N/A | H147: ADMINISTRATIVOS | I147: =VLOOKUP(Tabla3[[#This Row],[Deposito]],'SAPROV (2)'!D:E,2,FALSE) -> A01 | K147: COMISIONES BANCARIAS | L147: =VLOOKUP(Tabla3[[#This Row],[PROVEEDOR]],'SAPROV (2)'!A:B,2,FALSE) -> 04 | M147: =VLOOKUP(Tabla3[[#This Row],[SERVICIO]],'SAPROV (2)'!I:J,2,FALSE) -> SERV0060 | N147: ?COMISIONES BANCARIAS | P147: =VLOOKUP(Tabla3[[#This Row],[FECHA]],TASA[],2,FALSE) -> 358.92 | Q147: =D147/P147 -> -8.3584086 | R147: MERCANTIL
A148: 46049 | B148: 10781497448 | C148: COMISION POR TRANSFERENCIA DE FONDOS | D148: -3000 | E148: D | F148: =VLOOKUP(Tabla3[[#This Row],[CONTABLE]],'SAPROV (2)'!L:M,2,FALSE) -> #N/A | H148: ADMINISTRATIVOS | I148: =VLOOKUP(Tabla3[[#This Row],[Deposito]],'SAPROV (2)'!D:E,2,FALSE) -> A01 | K148: COMISIONES BANCARIAS | L148: =VLOOKUP(Tabla3[[#This Row],[PROVEEDOR]],'SAPROV (2)'!A:B,2,FALSE) -> 04 | M148: =VLOOKUP(Tabla3[[#This Row],[SERVICIO]],'SAPROV (2)'!I:J,2,FALSE) -> SERV0060 | N148: ?COMISIONES BANCARIAS | P148: =VLOOKUP(Tabla3[[#This Row],[FECHA]],TASA[],2,FALSE) -> 358.92 | Q148: =D148/P148 -> -8.3584086 | R148: MERCANTIL
A149: 46049 | B149: 10781497178 | C149: COMISION POR TRANSFERENCIA DE FONDOS | D149: -3000 | E149: D | F149: =VLOOKUP(Tabla3[[#This Row],[CONTABLE]],'SAPROV (2)'!L:M,2,FALSE) -> #N/A | H149: ADMINISTRATIVOS | I149: =VLOOKUP(Tabla3[[#This Row],[Deposito]],'SAPROV (2)'!D:E,2,FALSE) -> A01 | K149: COMISIONES BANCARIAS | L149: =VLOOKUP(Tabla3[[#This Row],[PROVEEDOR]],'SAPROV (2)'!A:B,2,FALSE) -> 04 | M149: =VLOOKUP(Tabla3[[#This Row],[SERVICIO]],'SAPROV (2)'!I:J,2,FALSE) -> SERV0060 | N149: ?COMISIONES BANCARIAS | P149: =VLOOKUP(Tabla3[[#This Row],[FECHA]],TASA[],2,FALSE) -> 358.92 | Q149: =D149/P149 -> -8.3584086 | R149: MERCANTIL
A150: 46049 | B150: 43700028344 | C150: OP.CRED.DIRT.CLTE-CLTE PJ JURIDICA ELECTRON | D150: -10.1 | E150: D | F150: =VLOOKUP(Tabla3[[#This Row],[CONTABLE]],'SAPROV (2)'!L:M,2,FALSE) -> #N/A | H150: ADMINISTRATIVOS | I150: =VLOOKUP(Tabla3[[#This Row],[Deposito]],'SAPROV (2)'!D:E,2,FALSE) -> A01 | K150: COMISIONES BANCARIAS | L150: =VLOOKUP(Tabla3[[#This Row],[PROVEEDOR]],'SAPROV (2)'!A:B,2,FALSE) -> 04 | M150: =VLOOKUP(Tabla3[[#This Row],[SERVICIO]],'SAPROV (2)'!I:J,2,FALSE) -> SERV0060 | N150: ?COMISIONES BANCARIAS | P150: =VLOOKUP(Tabla3[[#This Row],[FECHA]],TASA[],2,FALSE) -> 358.92 | Q150: =D150/P150 -> -0.028139975 | R150: MERCANTIL
A151: 46052 | B151: 71600000000 | C151: EMISION EDO. DEC TA.MONEDA NAC. EXT. | D151: -8 | E151: D | F151: =VLOOKUP(Tabla3[[#This Row],[CONTABLE]],'SAPROV (2)'!L:M,2,FALSE) -> #N/A | H151: ADMINISTRATIVOS | I151: =VLOOKUP(Tabla3[[#This Row],[Deposito]],'SAPROV (2)'!D:E,2,FALSE) -> A01 | K151: COMISIONES BANCARIAS | L151: =VLOOKUP(Tabla3[[#This Row],[PROVEEDOR]],'SAPROV (2)'!A:B,2,FALSE) -> 04 | M151: =VLOOKUP(Tabla3[[#This Row],[SERVICIO]],'SAPROV (2)'!I:J,2,FALSE) -> SERV0060 | N151: ?COMISIONES BANCARIAS | P151: =VLOOKUP(Tabla3[[#This Row],[FECHA]],TASA[],2,FALSE) -> 367.31 | Q151: =D151/P151 -> -0.021779968 | R151: MERCANTIL
A152: 46052 | B152: 91577700000 | C152: TARIFA MANTENIMIENTO DE CUENTA | D152: -8 | E152: D | F152: =VLOOKUP(Tabla3[[#This Row],[CONTABLE]],'SAPROV (2)'!L:M,2,FALSE) -> #N/A | H152: ADMINISTRATIVOS | I152: =VLOOKUP(Tabla3[[#This Row],[Deposito]],'SAPROV (2)'!D:E,2,FALSE) -> A01 | K152: COMISIONES BANCARIAS | L152: =VLOOKUP(Tabla3[[#This Row],[PROVEEDOR]],'SAPROV (2)'!A:B,2,FALSE) -> 04 | M152: =VLOOKUP(Tabla3[[#This Row],[SERVICIO]],'SAPROV (2)'!I:J,2,FALSE) -> SERV0060 | N152: ?COMISIONES BANCARIAS | P152: =VLOOKUP(Tabla3[[#This Row],[FECHA]],TASA[],2,FALSE) -> 367.31 | Q152: =D152/P152 -> -0.021779968 | R152: MERCANTIL
... A178: 46027 | B178: 5926 | C178: RECARGA DE 120 LITROS DE COMBUSTIBLE PERSONAL DEL SESAY | D178: -18282 | E178: D | F178: =VLOOKUP(Tabla3[[#This Row],[CONTABLE]],'SAPROV (2)'!L:M,2,FALSE) -> #N/A | H178: Pira café | I178: =VLOOKUP(Tabla3[[#This Row],[Deposito]],'SAPROV (2)'!D:E,2,FALSE) -> 02 | K178: COMBUSTIBLE | L178: =VLOOKUP(Tabla3[[#This Row],[PROVEEDOR]],'SAPROV (2)'!A:B,2,FALSE) -> 12 | M178: =VLOOKUP(Tabla3[[#This Row],[SERVICIO]],'SAPROV (2)'!I:J,2,FALSE) -> SERV0038 | N178: ?GASTOS COMBUSTIBLE/ GASOLINA | P178: =VLOOKUP(Tabla3[[#This Row],[FECHA]],TASA[],2,FALSE) -> 304.68 | Q178: =D178/P178 -> -60.003939 | R178: CAJA CHICA
A179: 46027 | C179: RECARGA DE 40 LITROS DE COMBUSTIBLE PERSONAL DEL SESAY | D179: -6509 | E179: D | F179: =VLOOKUP(Tabla3[[#This Row],[CONTABLE]],'SAPROV (2)'!L:M,2,FALSE) -> #N/A | H179: Pira café | I179: =VLOOKUP(Tabla3[[#This Row],[Deposito]],'SAPROV (2)'!D:E,2,FALSE) -> 02 | K179: COMBUSTIBLE | L179: =VLOOKUP(Tabla3[[#This Row],[PROVEEDOR]],'SAPROV (2)'!A:B,2,FALSE) -> 12 | M179: =VLOOKUP(Tabla3[[#This Row],[SERVICIO]],'SAPROV (2)'!I:J,2,FALSE) -> SERV0038 | N179: ?GASTOS COMBUSTIBLE/ GASOLINA | P179: =VLOOKUP(Tabla3[[#This Row],[FECHA]],TASA[],2,FALSE) -> 304.68 | Q179: =D179/P179 -> -21.363398 | R179: CAJA CHICA
A180: 46027 | B180: 2142 | C180: RECARGA DE 20 LITROS DE COMBUSTIBLE JOSE PINEDA | D180: -3046.8 | E180: D | F180: =VLOOKUP(Tabla3[[#This Row],[CONTABLE]],'SAPROV (2)'!L:M,2,FALSE) -> #N/A | H180: Productor Agro tendencias | I180: =VLOOKUP(Tabla3[[#This Row],[Deposito]],'SAPROV (2)'!D:E,2,FALSE) -> 07 | K180: COMBUSTIBLE | L180: =VLOOKUP(Tabla3[[#This Row],[PROVEEDOR]],'SAPROV (2)'!A:B,2,FALSE) -> 12 | M180: =VLOOKUP(Tabla3[[#This Row],[SERVICIO]],'SAPROV (2)'!I:J,2,FALSE) -> SERV0038 | N180: ?GASTOS COMBUSTIBLE/ GASOLINA | P180: =VLOOKUP(Tabla3[[#This Row],[FECHA]],TASA[],2,FALSE) -> 304.68 | Q180: =D180/P180 -> -10 | R180: CAJA CHICA
A181: 46027 | B181: 1040 | C181: MES DE ENERO AGRO TENDENCIA, C.A. | D181: -3616.44 | E181: D | F181: =VLOOKUP(Tabla3[[#This Row],[CONTABLE]],'SAPROV (2)'!L:M,2,FALSE) -> #N/A | H181: ADMINISTRATIVOS | I181: =VLOOKUP(Tabla3[[#This Row],[Deposito]],'SAPROV (2)'!D:E,2,FALSE) -> A01 | K181: SUNAGRO | L181: =VLOOKUP(Tabla3[[#This Row],[PROVEEDOR]],'SAPROV (2)'!A:B,2,FALSE) -> 10 | M181: =VLOOKUP(Tabla3[[#This Row],[SERVICIO]],'SAPROV (2)'!I:J,2,FALSE) -> SERV0145 | N181: GASTOS DE GUIA DE TRASLADO | P181: =VLOOKUP(Tabla3[[#This Row],[FECHA]],TASA[],2,FALSE) -> 304.68 | Q181: =D181/P181 -> -11.869634 | R181: CAJA CHICA
A182: 46028 | B182: 6876 | C182: RECARGA DE 10 LITROS DE GASOLINA MOTO ASIGNADA A DOMINGO DOMINGUEZ | D182: -1525 | E182: D | F182: =VLOOKUP(Tabla3[[#This Row],[CONTABLE]],'SAPROV (2)'!L:M,2,FALSE) -> #N/A | H182: Productor Agro tendencias | I182: =VLOOKUP(Tabla3[[#This Row],[Deposito]],'SAPROV (2)'!D:E,2,FALSE) -> 07 | K182: COMBUSTIBLE | L182: =VLOOKUP(Tabla3[[#This Row],[PROVEEDOR]],'SAPROV (2)'!A:B,2,FALSE) -> 12 | M182: =VLOOKUP(Tabla3[[#This Row],[SERVICIO]],'SAPROV (2)'!I:J,2,FALSE) -> SERV0038 | N182: ?GASTOS COMBUSTIBLE/ GASOLINA | P182: =VLOOKUP(Tabla3[[#This Row],[FECHA]],TASA[],2,FALSE) -> 308.15 | Q182: =D182/P182 -> -4.9488885 | R182: CAJA CHICA
A183: 46028 | B183: 3975 | C183: RECARGA DE 58 LITROS DE GASOLINA CAMIONETA LK 153 | D183: -8936.64 | E183: D | F183: =VLOOKUP(Tabla3[[#This Row],[CONTABLE]],'SAPROV (2)'!L:M,2,FALSE) -> #N/A | H183: ADMINISTRATIVOS | I183: =VLOOKUP(Tabla3[[#This Row],[Deposito]],'SAPROV (2)'!D:E,2,FALSE) -> A01 | K183: COMBUSTIBLE | L183: =VLOOKUP(Tabla3[[#This Row],[PROVEEDOR]],'SAPROV (2)'!A:B,2,FALSE) -> 12 | M183: =VLOOKUP(Tabla3[[#This Row],[SERVICIO]],'SAPROV (2)'!I:J,2,FALSE) -> SERV0038 | N183: ?GASTOS COMBUSTIBLE/ GASOLINA | P183: =VLOOKUP(Tabla3[[#This Row],[FECHA]],TASA[],2,FALSE) -> 308.15 | Q183: =D183/P183 -> -29.000941 | R183: CAJA CHICA
A184: 46028 | B184: 7394 | C184: RECARGA DE 70 LITROS DE GASOLINA CAMION BLANCO (OSCAR) | D184: -10785.6 | E184: D | F184: =VLOOKUP(Tabla3[[#This Row],[CONTABLE]],'SAPROV (2)'!L:M,2,FALSE) -> #N/A | H184: Productor Agro tendencias | I184: =VLOOKUP(Tabla3[[#This Row],[Deposito]],'SAPROV (2)'!D:E,2,FALSE) -> 07 | K184: COMBUSTIBLE | L184: =VLOOKUP(Tabla3[[#This Row],[PROVEEDOR]],'SAPROV (2)'!A:B,2,FALSE) -> 12 | M184: =VLOOKUP(Tabla3[[#This Row],[SERVICIO]],'SAPROV (2)'!I:J,2,FALSE) -> SERV0038 | N184: ?GASTOS COMBUSTIBLE/ GASOLINA | P184: =VLOOKUP(Tabla3[[#This Row],[FECHA]],TASA[],2,FALSE) -> 308.15 | Q184: =D184/P184 -> -35.001136 | R184: CAJA CHICA
A185: 46029 | B185: 152 | C185: RECARGA 10 LITROS DE GASOLINA MOTO ASIGNADA A JAVIER CHIRINO | D185: -1560 | E185: D | F185: =VLOOKUP(Tabla3[[#This Row],[CONTABLE]],'SAPROV (2)'!L:M,2,FALSE) -> #N/A | H185: Pira café | I185: =VLOOKUP(Tabla3[[#This Row],[Deposito]],'SAPROV (2)'!D:E,2,FALSE) -> 02 | K185: COMBUSTIBLE | L185: =VLOOKUP(Tabla3[[#This Row],[PROVEEDOR]],'SAPROV (2)'!A:B,2,FALSE) -> 12 | M185: =VLOOKUP(Tabla3[[#This Row],[SERVICIO]],'SAPROV (2)'!I:J,2,FALSE) -> SERV0038 | N185: ?GASTOS COMBUSTIBLE/ GASOLINA | P185: =VLOOKUP(Tabla3[[#This Row],[FECHA]],TASA[],2,FALSE) -> 311.88 | Q185: =D185/P185 -> -5.0019238 | R185: CAJA CHICA
A186: 46029 | B186: 5146 | C186: RECARGA DE 9 LITROS DE GASOLINA MOTO ASIGNADA A EUCARYS RODRIGUEZ | D186: -1457 | E186: D | F186: =VLOOKUP(Tabla3[[#This Row],[CONTABLE]],'SAPROV (2)'!L:M,2,FALSE) -> #N/A | H186: Pira café | I186: =VLOOKUP(Tabla3[[#This Row],[Deposito]],'SAPROV (2)'!D:E,2,FALSE) -> 02 | K186: COMBUSTIBLE | L186: =VLOOKUP(Tabla3[[#This Row],[PROVEEDOR]],'SAPROV (2)'!A:B,2,FALSE) -> 12 | M186: =VLOOKUP(Tabla3[[#This Row],[SERVICIO]],'SAPROV (2)'!I:J,2,FALSE) -> SERV0038 | N186: ?GASTOS COMBUSTIBLE/ GASOLINA | P186: =VLOOKUP(Tabla3[[#This Row],[FECHA]],TASA[],2,FALSE) -> 311.88 | Q186: =D186/P186 -> -4.6716686 | R186: CAJA CHICA
A187: 46029 | B187: 6251 | C187: RECARGA DE 140 LITROS DE GASOLINA PARA EL TRITON ROJO | D187: -21833 | E187: D | F187: =VLOOKUP(Tabla3[[#This Row],[CONTABLE]],'SAPROV (2)'!L:M,2,FALSE) -> #N/A | H187: Productor Agro tendencias | I187: =VLOOKUP(Tabla3[[#This Row],[Deposito]],'SAPROV (2)'!D:E,2,FALSE) -> 07 | K187: COMBUSTIBLE | L187: =VLOOKUP(Tabla3[[#This Row],[PROVEEDOR]],'SAPROV (2)'!A:B,2,FALSE) -> 12 | M187: =VLOOKUP(Tabla3[[#This Row],[SERVICIO]],'SAPROV (2)'!I:J,2,FALSE) -> SERV0038 | N187: ?GASTOS COMBUSTIBLE/ GASOLINA | P187: =VLOOKUP(Tabla3[[#This Row],[FECHA]],TASA[],2,FALSE) -> 311.88 | Q187: =D187/P187 -> -70.004489 | R187: CAJA CHICA
A188: 46029 | B188: 6396 | C188: RECARGA DE 40 LITROS DE COMBUSTIBLE PARA TOYOTA HEMBRITA | D188: -6238 | E188: D | F188: =VLOOKUP(Tabla3[[#This Row],[CONTABLE]],'SAPROV (2)'!L:M,2,FALSE) -> #N/A | H188: Pira café | I188: =VLOOKUP(Tabla3[[#This Row],[Deposito]],'SAPROV (2)'!D:E,2,FALSE) -> 02 | K188: COMBUSTIBLE | L188: =VLOOKUP(Tabla3[[#This Row],[PROVEEDOR]],'SAPROV (2)'!A:B,2,FALSE) -> 12 | M188: =VLOOKUP(Tabla3[[#This Row],[SERVICIO]],'SAPROV (2)'!I:J,2,FALSE) -> SERV0038 | N188: ?GASTOS COMBUSTIBLE/ GASOLINA | P188: =VLOOKUP(Tabla3[[#This Row],[FECHA]],TASA[],2,FALSE) -> 311.88 | Q188: =D188/P188 -> -20.001283 | R188: CAJA CHICA
...

Sheet SAPROV (2)
A1: ACRILICOS VIRGUEZ, C.A. | B1: J-085083766 | D1: Pira café | E1: 02 | G1: Campaña | I1: ? ADQUSICION DE HERRAMIENTAS/TALLER | J1: SERV0020 | L1: CAJA PUENTE TRANSITORIA | M1: 110101001
A2: ADQUISION | B2: 47 | D2: Pira Caraota | E2: 03 | I2: ? ADQUSICION DE HERRAMIENTAS/TALLER | J2: SERV0020E | L2: CARGOS TRANSITORIOS TRASPASO | M2: 110101003
A3: AGRICOLA NOVATERRA | B3: J500597193 | D3: Pira Arroz | E3: 04 | I3: ?ADQUISICION BIENES INMUEBLES | J3: SERV0056 | L3: BANCO DEL TESORO | M3: 110102001
A4: AGROFERRETERIA CAMPO ALEGRE | B4: J296883335 | D4: no usar | E4: 05 | I4: ?ADQUISICION BIENES INMUEBLES | J4: SERV0056E | L4: BANESCO | M4: 110102002
A5: AGROPACA | B5: J412594982 | D5: Leguminosa | E5: 06 | I5: ?ADQUISICION BIENES MUEBLES | J5: SERV0057 | L5: PROVINCIAL | M5: 110102003
A6: AGROPECUARIA LAS DOS QUEBRADAS | B6: J308039209 | D6: Exportacion | E6: 08 | I6: ?ADQUISICION BIENES MUEBLES | J6: SERV0057E | L6: BANCO DE VENEZUELA | M6: 110102004
A7: AGROPLUS VENEZUELA C.A | B7: J-50044103-7 | D7: ADMINISTRATIVOS | E7: A01 | I7: ?ADQUISICION DE EQUIPOS DE LABORATORIO | J7: SERV0128 | L7: BANCO NACIONAL DE CREDITO BNC | M7: 110102005
A8: AGROTOTAL 2011, SA | B8: J-400085799 | D8: Pira Maíz | E8: 01 | I8: ?ADQUISICION DE EQUIPOS DE LABORATORIO | J8: SERV0128E | L8: BICENTENARIO AGRO | M8: 110102006
A9: ALCALDIA | B9: 09 | D9: Productor Agro tendencias | E9: 07 | I9: ?ADQUISICION MOBILIARIO | J9: SERV0055 | L9: MERCANTIL AGRO | M9: 110102007
A10: ALCALDIA URACHICHE | B10: G200045507 | D10: no usar | E10: 09 | I10: ?ADQUISICION MOBILIARIO | J10: SERV0055E | L10: TITULO DE COBERTURA BANESCO | M10: 110105001
A11: ALEXI FRANCISCO QUINTERO | B11: V047314000 | I11: ?BENEFICIO ALIMENTICIO | J11: SERV0202 | L11: TITULO DE COBERTURA TESORO | M11: 110105004
A12: ALISMERI ROJAS | B12: V20468697 | I12: ?BENEFICIO ALIMENTICIO | J12: SERV0202E | L12: TITULO DE COBERTURA BICENTENARIO | M12: 110105005
A13: ANGEL MORALES | B13: V22314455 | I13: ?CARGA Y DESGARGA DE GANDOLA | J13: SERV0207 | L13: CUENTAS POR COBRAR CLIENTES | M13: 110106001
A14: ANGEL SILVA | B14: 73 | I14: ?CARGA Y DESGARGA DE GANDOLA | J14: SERV0207E | L14: CUENTAS POR COBRAR HERAS NEW FASHION | M14: 110106012
A15: ANGEL SILVA | B15: V199723873 | I15: ?COMISIONES BANCARIAS | J15: SERV0060 | L15: CUENTAS POR COBRAR TENDENCIAS AB, C.A. | M15: 110106013
A16: ANGELA ILARRAZA | B16: V4772646 | I16: ?COMISIONES BANCARIAS | J16: SERV0060E | L16: CUENTAS POR COBRAR INDUSTRIA AGROTENDENCIAS | M16: 110106019
A17: ANSWERS TECNIT SERVIT, C.A | B17: J-400489326 | I17: ?COMISIONES ESPECIALES | J17: SERV0068 | L17: CUENTAS POR COBRAR SILOS AGROTENDENCIAS | M17: 110106025
A18: ANTIOQUIO GALINDEZ | B18: V7550846 | I18: ?COMISIONES ESPECIALES | J18: SERV0068E | L18: CUENTAS POR COBRAR CLIENTES | M18: 110106099
A19: ANTONIO DURAN | B19: V6701712 | I19: ?COMPRA DE SEMILLA | J19: SERV0148 | L19: CUENTAS POR COBRAR PROVEEDORES | M19: 110107001
A20: ANYELBI DAVID GALINDEZ | B20: V20320699 | I20: ?COMPRA DE SEMILLA | J20: SERV0148E | L20: EFECTOS POR COBRAR | M20: 110110001
A21: ARACAL/CIARA | B21: 71 | I21: ?COMPRA FERTILIZANTE | J21: SERV0149E | L21: CUENTAS POR COBRAR EMPLEADOS | M21: 110113001
A22: ARCILIO DURAN | B22: 16261437 | I22: ?COMPRA VEHICULO/ACTIVO | J22: SERV0066 | L22: ANTICIPO PROVEDORES | M22: 110114001
... A225: ORGANISMOS GUBERNAMENTALES | B225: 40 | I225: IMPUESTO IGTF (pago divisas) | J225: SERV0127E | L225: ADQUISICION DE MAQUINARIA | M225: 730101028
A226: ORINOCO GRILL C.A | B226: J402118317 | L226: MANTENIMIENTO DE MAQUINARIAS INSUMOS | M226: 730101029
A227: ORINOCO GRILL C.A | B227: J50128967-0 | L227: MANTENIMIENTO MAQUINARIAS MANO DE OBRA | M227: 730101030
A228: ORVAL SA | B228: J307387831 | L228: FERTILIZANTES | M228: 730101031
A229: OSWALDO COLMENAREZ | B229: V7437664 | L229: GASTOS TRAMITES BOMBEROS | M229: 730101032
A230: OVIDIO PALERMO | B230: V11652864 | L230: GASTOS ARACAL/CIARA | M230: 730101033
A231: PABLO GERARDO LEON GUAREMAL MOTOS | B231: V108576908 | L231: GASTOS NOTARIAS | M231: 730101034
A232: PAGO EFECTIVO | B232: 34 | L232: ADQUISICION DE INMUEBLE | M232: 730101035
A233: PARAFISCALES | B233: 03 | L233: ADQUISICION DE BIENES MUEBLES | M233: 730101036
A234: PERMISOS | B234: 08 | L234: PREMIO MOVILIDAD | M234: 730101037
A235: PLASTISERIES C.A | B235: J310141932 | L235: INSUMOS TALLER | M235: 730101038
A236: PRESTAMOS | B236: 46 | L236: BONO COMPLEMENTARIO | M236: 740101001
A237: PRODUCCION | B237: 22 | L237: SALARIO BASE QUINCENAL | M237: 740101002
... A240: PUBLICIDAD | B240: 30 | L240: DESCUENTO POR FINANCIAMIENTO | M240: 840101003
A241: QUALITY MOTORS , C.A | B241: J-409850129
A242: RAFAEL OSCAR PACHECO CASTILLO | B242: V115207519
A243: REFRIGERIOS | B243: 13
A244: REPRESENTACIONES LUIMAR CA | B244: J304837666
...

Sheet TASA
B3: FECHA | C3: TASA
B4: 46023 | C4: 301.37
B5: 46024 | C5: 301.37
B6: 46025 | C6: 304.68
B7: 46026 | C7: 304.68
B8: 46027 | C8: 304.68
B9: 46028 | C9: 308.15
B10: 46029 | C10: 311.88
B11: 46030 | C11: 321.03
B12: 46031 | C12: 325.39
B13: 46032 | C13: 330.38
B14: 46033 | C14: 330.38
B15: 46034 | C15: 330.38
... B34: 46053 | C34: 370.25
